Workbook

Sheet gelecek
B1: United States | C1: Sweden | D1: China | E1: Poland | F1: Germany | G1: Ireland | H1: Canada | I1: Netherlands | J1: France | K1: United Kingdom | L1: Fildişi Sahili | M1: Ekvador | N1: Estonya | O1: Kenya | P1: Lüksemburg | Q1: Singapur | R1: Slovakya | S1: İsviçre | T1: Tanzanya | U1: Tunus | V1: Türkmenistan | W1: Azerbaycan | X1: Italy | Y1: South Korea | Z1: Croatia | AA1: Türkiye | AB1: Mısır
A2: 46309 | T2: Nyerere Day (Nyerere'yi Anma Günü)
A3: 46310 | U3: Evacuation Day (Tahliye Günü)
A4: 46315 | O4: Mashujaa Day (Kahramanlar Günü)
A5: 46323 | AA5: Republic Day Eve (Cumhuriyet Bayramı Arifesi)
A6: 46324 | AA6: Republic Day (Cumhuriyet Bayramı)
A7: 46327 | L7: All Saints' Day (Azizler Günü) | P7: All Saints' Day (Azizler Günü) | X7: All Saints' Day (Azizler Günü) | Z7: All Saints' Day (Azizler Günü)
A8: 46328 | M8: All Souls' Day (Ölüleri Anma Günü)
A9: 46329 | M9: Independence of Cuenca (Cuenca'nın Bağımsızlığı)
A10: 46334 | Q10: Deepavali / Diwali (Işık Festivali) | W10: Victory Day (Zafer Günü)
A11: 46335 | W11: State Flag Day (Devlet Bayrağı Günü)
A12: 46336 | AA12: Atatürk'ü Anma Günü
A13: 46337 | E13: Narodowe Święto Niepodległości (Bağımsızlık Günü)
A14: 46341 | L14: National Peace Day (Ulusal Barış Günü)
A15: 46343 | R15: Freedom and Democracy Day (Özgürlük ve Demokrasi Günü)
A16: 46344 | Z16: Remembrance Day (Anma Günü)
A17: 46350 | AA17: Öğretmenler Günü
A18: 46352 | B18: Thanksgiving (Şükran Günü)
A19: 46359 | AA19: Dünya Engelliler Günü
A20: 46364 | X20: Immaculate Conception (Meryem'in Günahsızlığı Bayramı)
A21: 46365 | T21: Independence and Republic Day (Bağımsızlık ve Cumhuriyet Günü)
A22: 46368 | O22: Jamhuri Day (Cumhuriyet Günü) | V22: International Day of Neutrality (Uluslararası Tarafsızlık Günü)
A23: 46373 | U23: Revolution and Youth Day (Devrim ve Gençlik Günü)
A24: 46380
A25: 46381
A26: 46382
A27: 0

Sheet Sayfa1
D2: =IF(gelecek!B1<>"",gelecek!B1,"") -> United States | E2: =IF(gelecek!C1<>"",gelecek!C1,"") -> Sweden | F2: =IF(gelecek!D1<>"",gelecek!D1,"") -> China | G2: =IF(gelecek!E1<>"",gelecek!E1,"") -> Poland | H2: =IF(gelecek!F1<>"",gelecek!F1,"") -> Germany | I2: =IF(gelecek!G1<>"",gelecek!G1,"") -> Ireland | J2: =IF(gelecek!H1<>"",gelecek!H1,"") -> Canada | K2: =IF(gelecek!I1<>"",gelecek!I1,"") -> Netherlands | ... AD2: =IF(gelecek!AB1<>"",gelecek!AB1,"") -> Mısır
C3: =gelecek!A2 -> 46309 | D3: =IF(gelecek!B2<>"",gelecek!B2,"") | E3: =IF(gelecek!C2<>"",gelecek!C2,"") | F3: =IF(gelecek!D2<>"",gelecek!D2,"") | G3: =IF(gelecek!E2<>"",gelecek!E2,"") | H3: =IF(gelecek!F2<>"",gelecek!F2,"") | I3: =IF(gelecek!G2<>"",gelecek!G2,"") | J3: =IF(gelecek!H2<>"",gelecek!H2,"") | K3: =IF(gelecek!I2<>"",gelecek!I2,"") | ... AD3: =IF(gelecek!AB2<>"",gelecek!AB2,"")
C4: =gelecek!A3 -> 46310 | D4: =IF(gelecek!B3<>"",gelecek!B3,"") | E4: =IF(gelecek!C3<>"",gelecek!C3,"") | F4: =IF(gelecek!D3<>"",gelecek!D3,"") | G4: =IF(gelecek!E3<>"",gelecek!E3,"") | H4: =IF(gelecek!F3<>"",gelecek!F3,"") | I4: =IF(gelecek!G3<>"",gelecek!G3,"") | J4: =IF(gelecek!H3<>"",gelecek!H3,"") | K4: =IF(gelecek!I3<>"",gelecek!I3,"") | ... AD4: =IF(gelecek!AB3<>"",gelecek!AB3,"")
C5: =gelecek!A4 -> 46315 | D5: =IF(gelecek!B4<>"",gelecek!B4,"") | E5: =IF(gelecek!C4<>"",gelecek!C4,"") | F5: =IF(gelecek!D4<>"",gelecek!D4,"") | G5: =IF(gelecek!E4<>"",gelecek!E4,"") | H5: =IF(gelecek!F4<>"",gelecek!F4,"") | I5: =IF(gelecek!G4<>"",gelecek!G4,"") | J5: =IF(gelecek!H4<>"",gelecek!H4,"") | K5: =IF(gelecek!I4<>"",gelecek!I4,"") | ... AD5: =IF(gelecek!AB4<>"",gelecek!AB4,"")
C6: =gelecek!A5 -> 46323 | D6: =IF(gelecek!B5<>"",gelecek!B5,"") | E6: =IF(gelecek!C5<>"",gelecek!C5,"") | F6: =IF(gelecek!D5<>"",gelecek!D5,"") | G6: =IF(gelecek!E5<>"",gelecek!E5,"") | H6: =IF(gelecek!F5<>"",gelecek!F5,"") | I6: =IF(gelecek!G5<>"",gelecek!G5,"") | J6: =IF(gelecek!H5<>"",gelecek!H5,"") | K6: =IF(gelecek!I5<>"",gelecek!I5,"") | ... AD6: =IF(gelecek!AB5<>"",gelecek!AB5,"")
C7: =gelecek!A6 -> 46324 | D7: =IF(gelecek!B6<>"",gelecek!B6,"") | E7: =IF(gelecek!C6<>"",gelecek!C6,"") | F7: =IF(gelecek!D6<>"",gelecek!D6,"") | G7: =IF(gelecek!E6<>"",gelecek!E6,"") | H7: =IF(gelecek!F6<>"",gelecek!F6,"") | I7: =IF(gelecek!G6<>"",gelecek!G6,"") | J7: =IF(gelecek!H6<>"",gelecek!H6,"") | K7: =IF(gelecek!I6<>"",gelecek!I6,"") | ... AD7: =IF(gelecek!AB6<>"",gelecek!AB6,"")
C8: =gelecek!A7 -> 46327 | D8: =IF(gelecek!B7<>"",gelecek!B7,"") | E8: =IF(gelecek!C7<>"",gelecek!C7,"") | F8: =IF(gelecek!D7<>"",gelecek!D7,"") | G8: =IF(gelecek!E7<>"",gelecek!E7,"") | H8: =IF(gelecek!F7<>"",gelecek!F7,"") | I8: =IF(gelecek!G7<>"",gelecek!G7,"") | J8: =IF(gelecek!H7<>"",gelecek!H7,"") | K8: =IF(gelecek!I7<>"",gelecek!I7,"") | ... AD8: =IF(gelecek!AB7<>"",gelecek!AB7,"")
C9: =gelecek!A8 -> 46328 | D9: =IF(gelecek!B8<>"",gelecek!B8,"") | E9: =IF(gelecek!C8<>"",gelecek!C8,"") | F9: =IF(gelecek!D8<>"",gelecek!D8,"") | G9: =IF(gelecek!E8<>"",gelecek!E8,"") | H9: =IF(gelecek!F8<>"",gelecek!F8,"") | I9: =IF(gelecek!G8<>"",gelecek!G8,"") | J9: =IF(gelecek!H8<>"",gelecek!H8,"") | K9: =IF(gelecek!I8<>"",gelecek!I8,"") | ... AD9: =IF(gelecek!AB8<>"",gelecek!AB8,"")
C10: =gelecek!A9 -> 46329 | D10: =IF(gelecek!B9<>"",gelecek!B9,"") | E10: =IF(gelecek!C9<>"",gelecek!C9,"") | F10: =IF(gelecek!D9<>"",gelecek!D9,"") | G10: =IF(gelecek!E9<>"",gelecek!E9,"") | H10: =IF(gelecek!F9<>"",gelecek!F9,"") | I10: =IF(gelecek!G9<>"",gelecek!G9,"") | J10: =IF(gelecek!H9<>"",gelecek!H9,"") | K10: =IF(gelecek!I9<>"",gelecek!I9,"") | ... AD10: =IF(gelecek!AB9<>"",gelecek!AB9,"")
C11: =gelecek!A10 -> 46334 | D11: =IF(gelecek!B10<>"",gelecek!B10,"") | E11: =IF(gelecek!C10<>"",gelecek!C10,"") | F11: =IF(gelecek!D10<>"",gelecek!D10,"") | G11: =IF(gelecek!E10<>"",gelecek!E10,"") | H11: =IF(gelecek!F10<>"",gelecek!F10,"") | I11: =IF(gelecek!G10<>"",gelecek!G10,"") | J11: =IF(gelecek!H10<>"",gelecek!H10,"") | K11: =IF(gelecek!I10<>"",gelecek!I10,"") | ... AD11: =IF(gelecek!AB10<>"",gelecek!AB10,"")
C12: =gelecek!A11 -> 46335 | D12: =IF(gelecek!B11<>"",gelecek!B11,"") | E12: =IF(gelecek!C11<>"",gelecek!C11,"") | F12: =IF(gelecek!D11<>"",gelecek!D11,"") | G12: =IF(gelecek!E11<>"",gelecek!E11,"") | H12: =IF(gelecek!F11<>"",gelecek!F11,"") | I12: =IF(gelecek!G11<>"",gelecek!G11,"") | J12: =IF(gelecek!H11<>"",gelecek!H11,"") | K12: =IF(gelecek!I11<>"",gelecek!I11,"") | ... AD12: =IF(gelecek!AB11<>"",gelecek!AB11,"")
C13: =gelecek!A12 -> 46336 | D13: =IF(gelecek!B12<>"",gelecek!B12,"") | E13: =IF(gelecek!C12<>"",gelecek!C12,"") | F13: =IF(gelecek!D12<>"",gelecek!D12,"") | G13: =IF(gelecek!E12<>"",gelecek!E12,"") | H13: =IF(gelecek!F12<>"",gelecek!F12,"") | I13: =IF(gelecek!G12<>"",gelecek!G12,"") | J13: =IF(gelecek!H12<>"",gelecek!H12,"") | K13: =IF(gelecek!I12<>"",gelecek!I12,"") | ... AD13: =IF(gelecek!AB12<>"",gelecek!AB12,"")
C14: =gelecek!A13 -> 46337 | D14: =IF(gelecek!B13<>"",gelecek!B13,"") | E14: =IF(gelecek!C13<>"",gelecek!C13,"") | F14: =IF(gelecek!D13<>"",gelecek!D13,"") | G14: =IF(gelecek!E13<>"",gelecek!E13,"") -> Narodowe Święto Niepodległości (Bağımsızlık Günü) | H14: =IF(gelecek!F13<>"",gelecek!F13,"") | I14: =IF(gelecek!G13<>"",gelecek!G13,"") | J14: =IF(gelecek!H13<>"",gelecek!H13,"") | K14: =IF(gelecek!I13<>"",gelecek!I13,"") | ... AD14: =IF(gelecek!AB13<>"",gelecek!AB13,"")
... C27: =gelecek!A26 -> 46382 | D27: =IF(gelecek!B26<>"",gelecek!B26,"") | E27: =IF(gelecek!C26<>"",gelecek!C26,"") | F27: =IF(gelecek!D26<>"",gelecek!D26,"") | G27: =IF(gelecek!E26<>"",gelecek!E26,"") | H27: =IF(gelecek!F26<>"",gelecek!F26,"") | I27: =IF(gelecek!G26<>"",gelecek!G26,"") | J27: =IF(gelecek!H26<>"",gelecek!H26,"") | K27: =IF(gelecek!I26<>"",gelecek!I26,"") | ... AD27: =IF(gelecek!AB26<>"",gelecek!AB26,"")
D28: =D2 -> United States | E28: =E2 -> Sweden | F28: =F2 -> China | G28: =G2 -> Poland | H28: =H2 -> Germany | I28: =I2 -> Ireland | J28: =J2 -> Canada | K28: =K2 -> Netherlands | ... AD28: =AD2 -> Mısır
B29: =D28 -> United States | C29: =IF(C3<>"",C3,"") -> 46309 | D29: =IF(D3<>"",D3,"") | E29: =IF(E3<>"",E3,"") | F29: =IF(F3<>"",F3,"") | G29: =IF(G3<>"",G3,"") | H29: =IF(H3<>"",H3,"") | I29: =IF(I3<>"",I3,"") | J29: =IF(J3<>"",J3,"") | ... AD29: =IF(AD3<>"",AD3,"")
B30: =B29 -> United States | C30: =IF(C4<>"",C4,"") -> 46310 | D30: =IF(D4<>"",D4,"") | E30: =IF(E4<>"",E4,"") | F30: =IF(F4<>"",F4,"") | G30: =IF(G4<>"",G4,"") | H30: =IF(H4<>"",H4,"") | I30: =IF(I4<>"",I4,"") | J30: =IF(J4<>"",J4,"") | ... AD30: =IF(AD4<>"",AD4,"")
B31: =B30 -> United States | C31: =IF(C5<>"",C5,"") -> 46315 | D31: =IF(D5<>"",D5,"") | E31: =IF(E5<>"",E5,"") | F31: =IF(F5<>"",F5,"") | G31: =IF(G5<>"",G5,"") | H31: =IF(H5<>"",H5,"") | I31: =IF(I5<>"",I5,"") | J31: =IF(J5<>"",J5,"") | ... AD31: =IF(AD5<>"",AD5,"")
B32: =B31 -> United States | C32: =IF(C6<>"",C6,"") -> 46323 | D32: =IF(D6<>"",D6,"") | E32: =IF(E6<>"",E6,"") | F32: =IF(F6<>"",F6,"") | G32: =IF(G6<>"",G6,"") | H32: =IF(H6<>"",H6,"") | I32: =IF(I6<>"",I6,"") | J32: =IF(J6<>"",J6,"") | ... AD32: =IF(AD6<>"",AD6,"")
B33: =B32 -> United States | C33: =IF(C7<>"",C7,"") -> 46324 | D33: =IF(D7<>"",D7,"") | E33: =IF(E7<>"",E7,"") | F33: =IF(F7<>"",F7,"") | G33: =IF(G7<>"",G7,"") | H33: =IF(H7<>"",H7,"") | I33: =IF(I7<>"",I7,"") | J33: =IF(J7<>"",J7,"") | ... AD33: =IF(AD7<>"",AD7,"")
B34: =B33 -> United States | C34: =IF(C8<>"",C8,"") -> 46327 | D34: =IF(D8<>"",D8,"") | E34: =IF(E8<>"",E8,"") | F34: =IF(F8<>"",F8,"") | G34: =IF(G8<>"",G8,"") | H34: =IF(H8<>"",H8,"") | I34: =IF(I8<>"",I8,"") | J34: =IF(J8<>"",J8,"") | ... AD34: =IF(AD8<>"",AD8,"")
B35: =B34 -> United States | C35: =IF(C9<>"",C9,"") -> 46328 | D35: =IF(D9<>"",D9,"") | E35: =IF(E9<>"",E9,"") | F35: =IF(F9<>"",F9,"") | G35: =IF(G9<>"",G9,"") | H35: =IF(H9<>"",H9,"") | I35: =IF(I9<>"",I9,"") | J35: =IF(J9<>"",J9,"") | ... AD35: =IF(AD9<>"",AD9,"")
B36: =B35 -> United States | C36: =IF(C10<>"",C10,"") -> 46329 | D36: =IF(D10<>"",D10,"") | E36: =IF(E10<>"",E10,"") | F36: =IF(F10<>"",F10,"") | G36: =IF(G10<>"",G10,"") | H36: =IF(H10<>"",H10,"") | I36: =IF(I10<>"",I10,"") | J36: =IF(J10<>"",J10,"") | ... AD36: =IF(AD10<>"",AD10,"")
B37: =B36 -> United States | C37: =IF(C11<>"",C11,"") -> 46334 | D37: =IF(D11<>"",D11,"") | E37: =IF(E11<>"",E11,"") | F37: =IF(F11<>"",F11,"") | G37: =IF(G11<>"",G11,"") | H37: =IF(H11<>"",H11,"") | I37: =IF(I11<>"",I11,"") | J37: =IF(J11<>"",J11,"") | ... AD37: =IF(AD11<>"",AD11,"")
B38: =B37 -> United States | C38: =IF(C12<>"",C12,"") -> 46335 | D38: =IF(D12<>"",D12,"") | E38: =IF(E12<>"",E12,"") | F38: =IF(F12<>"",F12,"") | G38: =IF(G12<>"",G12,"") | H38: =IF(H12<>"",H12,"") | I38: =IF(I12<>"",I12,"") | J38: =IF(J12<>"",J12,"") | ... AD38: =IF(AD12<>"",AD12,"")
B39: =B38 -> United States | C39: =IF(C13<>"",C13,"") -> 46336 | D39: =IF(D13<>"",D13,"") | E39: =IF(E13<>"",E13,"") | F39: =IF(F13<>"",F13,"") | G39: =IF(G13<>"",G13,"") | H39: =IF(H13<>"",H13,"") | I39: =IF(I13<>"",I13,"") | J39: =IF(J13<>"",J13,"") | ... AD39: =IF(AD13<>"",AD13,"")
B40: =B39 -> United States | C40: =IF(C14<>"",C14,"") -> 46337 | D40: =IF(D14<>"",D14,"") | E40: =IF(E14<>"",E14,"") | F40: =IF(F14<>"",F14,"") | G40: =IF(G14<>"",G14,"") -> Narodowe Święto Niepodległości (Bağımsızlık Günü) | H40: =IF(H14<>"",H14,"") | I40: =IF(I14<>"",I14,"") | J40: =IF(J14<>"",J14,"") | ... AD40: =IF(AD14<>"",AD14,"")
B41: =B40 -> United States | C41: =IF(C15<>"",C15,"") -> 46341 | D41: =IF(D15<>"",D15,"") | E41: =IF(E15<>"",E15,"") | F41: =IF(F15<>"",F15,"") | G41: =IF(G15<>"",G15,"") | H41: =IF(H15<>"",H15,"") | I41: =IF(I15<>"",I15,"") | J41: =IF(J15<>"",J15,"") | ... AD41: =IF(AD15<>"",AD15,"")
... B53: =B52 -> United States | C53: =IF(C27<>"",C27,"") -> 46382 | D53: =IF(D27<>"",D27,"") | E53: =IF(E27<>"",E27,"") | F53: =IF(F27<>"",F27,"") | G53: =IF(G27<>"",G27,"") | H53: =IF(H27<>"",H27,"") | I53: =IF(I27<>"",I27,"") | J53: =IF(J27<>"",J27,"") | ... AD53: =IF(AD27<>"",AD27,"")
D54: =E28 -> Sweden | E54: =F28 -> China | F54: =G28 -> Poland | G54: =H28 -> Germany | H54: =I28 -> Ireland | I54: =J28 -> Canada | J54: =K28 -> Netherlands | K54: =L28 -> France | ... AC54: =AD28 -> Mısır
B55: =D54 -> Sweden | C55: =IF(C29<>"",C29,"") -> 46309 | D55: =IF(E29<>"",E29,"") | E55: =IF(F29<>"",F29,"") | F55: =IF(G29<>"",G29,"") | G55: =IF(H29<>"",H29,"") | H55: =IF(I29<>"",I29,"") | I55: =IF(J29<>"",J29,"") | J55: =IF(K29<>"",K29,"") | K55: =IF(L29<>"",L29,"") | ... AC55: =IF(AD29<>"",AD29,"")
B56: =B55 -> Sweden | C56: =IF(C30<>"",C30,"") -> 46310 | D56: =IF(E30<>"",E30,"") | E56: =IF(F30<>"",F30,"") | F56: =IF(G30<>"",G30,"") | G56: =IF(H30<>"",H30,"") | H56: =IF(I30<>"",I30,"") | I56: =IF(J30<>"",J30,"") | J56: =IF(K30<>"",K30,"") | K56: =IF(L30<>"",L30,"") | ... AC56: =IF(AD30<>"",AD30,"")
B57: =B56 -> Sweden | C57: =IF(C31<>"",C31,"") -> 46315 | D57: =IF(E31<>"",E31,"") | E57: =IF(F31<>"",F31,"") | F57: =IF(G31<>"",G31,"") | G57: =IF(H31<>"",H31,"") | H57: =IF(I31<>"",I31,"") | I57: =IF(J31<>"",J31,"") | J57: =IF(K31<>"",K31,"") | K57: =IF(L31<>"",L31,"") | ... AC57: =IF(AD31<>"",AD31,"")
B58: =B57 -> Sweden | C58: =IF(C32<>"",C32,"") -> 46323 | D58: =IF(E32<>"",E32,"") | E58: =IF(F32<>"",F32,"") | F58: =IF(G32<>"",G32,"") | G58: =IF(H32<>"",H32,"") | H58: =IF(I32<>"",I32,"") | I58: =IF(J32<>"",J32,"") | J58: =IF(K32<>"",K32,"") | K58: =IF(L32<>"",L32,"") | ... AC58: =IF(AD32<>"",AD32,"")
B59: =B58 -> Sweden | C59: =IF(C33<>"",C33,"") -> 46324 | D59: =IF(E33<>"",E33,"") | E59: =IF(F33<>"",F33,"") | F59: =IF(G33<>"",G33,"") | G59: =IF(H33<>"",H33,"") | H59: =IF(I33<>"",I33,"") | I59: =IF(J33<>"",J33,"") | J59: =IF(K33<>"",K33,"") | K59: =IF(L33<>"",L33,"") | ... AC59: =IF(AD33<>"",AD33,"")
B60: =B59 -> Sweden | C60: =IF(C34<>"",C34,"") -> 46327 | D60: =IF(E34<>"",E34,"") | E60: =IF(F34<>"",F34,"") | F60: =IF(G34<>"",G34,"") | G60: =IF(H34<>"",H34,"") | H60: =IF(I34<>"",I34,"") | I60: =IF(J34<>"",J34,"") | J60: =IF(K34<>"",K34,"") | K60: =IF(L34<>"",L34,"") | ... AC60: =IF(AD34<>"",AD34,"")
B61: =B60 -> Sweden | C61: =IF(C35<>"",C35,"") -> 46328 | D61: =IF(E35<>"",E35,"") | E61: =IF(F35<>"",F35,"") | F61: =IF(G35<>"",G35,"") | G61: =IF(H35<>"",H35,"") | H61: =IF(I35<>"",I35,"") | I61: =IF(J35<>"",J35,"") | J61: =IF(K35<>"",K35,"") | K61: =IF(L35<>"",L35,"") | ... AC61: =IF(AD35<>"",AD35,"")
B62: =B61 -> Sweden | C62: =IF(C36<>"",C36,"") -> 46329 | D62: =IF(E36<>"",E36,"") | E62: =IF(F36<>"",F36,"") | F62: =IF(G36<>"",G36,"") | G62: =IF(H36<>"",H36,"") | H62: =IF(I36<>"",I36,"") | I62: =IF(J36<>"",J36,"") | J62: =IF(K36<>"",K36,"") | K62: =IF(L36<>"",L36,"") | ... AC62: =IF(AD36<>"",AD36,"")
B63: =B62 -> Sweden | C63: =IF(C37<>"",C37,"") -> 46334 | D63: =IF(E37<>"",E37,"") | E63: =IF(F37<>"",F37,"") | F63: =IF(G37<>"",G37,"") | G63: =IF(H37<>"",H37,"") | H63: =IF(I37<>"",I37,"") | I63: =IF(J37<>"",J37,"") | J63: =IF(K37<>"",K37,"") | K63: =IF(L37<>"",L37,"") | ... AC63: =IF(AD37<>"",AD37,"")
B64: =B63 -> Sweden | C64: =IF(C38<>"",C38,"") -> 46335 | D64: =IF(E38<>"",E38,"") | E64: =IF(F38<>"",F38,"") | F64: =IF(G38<>"",G38,"") | G64: =IF(H38<>"",H38,"") | H64: =IF(I38<>"",I38,"") | I64: =IF(J38<>"",J38,"") | J64: =IF(K38<>"",K38,"") | K64: =IF(L38<>"",L38,"") | ... AC64: =IF(AD38<>"",AD38,"")
...

Sheet Sayfa2
B2: Tanzanya | C2: 46309 | D2: Nyerere Day (Nyerere'yi Anma Günü)
B3: Tunus | C3: 46310 | D3: Evacuation Day (Tahliye Günü)
B4: Kenya | C4: 46315 | D4: Mashujaa Day (Kahramanlar Günü)
B5: Türkiye | C5: 46323 | D5: Republic Day Eve (Cumhuriyet Bayramı Arifesi)
B6: Türkiye | C6: 46324 | D6: Republic Day (Cumhuriyet Bayramı)
B7: Croatia | C7: 46327 | D7: All Saints' Day (Azizler Günü)
B8: Fildişi Sahili | C8: 46327 | D8: All Saints' Day (Azizler Günü)
B9: Italy | C9: 46327 | D9: All Saints' Day (Azizler Günü)
B10: Lüksemburg | C10: 46327 | D10: All Saints' Day (Azizler Günü)
B11: Ekvador | C11: 46328 | D11: All Souls' Day (Ölüleri Anma Günü)
B12: Ekvador | C12: 46329 | D12: Independence of Cuenca (Cuenca'nın Bağımsızlığı)
B13: Azerbaycan | C13: 46334 | D13: Victory Day (Zafer Günü)
... B28: Tunus | C28: 46373 | D28: Revolution and Youth Day (Devrim ve Gençlik Günü)

Sheet geçen
B1: United States | C1: Sweden | D1: China | E1: Poland | F1: Germany | G1: Ireland | H1: Canada | I1: Netherlands | J1: France | K1: United Kingdom | L1: Fildişi Sahili | M1: Ekvador | N1: Estonya | O1: Kenya | P1: Lüksemburg | Q1: Singapur | R1: Slovakya | S1: İsviçre | T1: Tanzanya | U1: Tunus | V1: Türkmenistan | W1: Azerbaycan | X1: Italy | Y1: South Korea | Z1: Croatia | AA1: Türkiye | AB1: Mısır
A2: 46023 | B2: New Year's Day (Yılbaşı) | C2: Nyårsdagen (Yılbaşı) | D2: New Year's Day (Yılbaşı) | E2: Nowy Rok (Yılbaşı) | F2: Neujahr (Yılbaşı) | G2: New Year's Day (Yılbaşı) | H2: New Year's Day (Yılbaşı) | I2: Nieuwjaar (Yılbaşı) | J2: Jour de l'an (Yılbaşı) | K2: New Year's Day (Yılbaşı) | L2: New Year's Day (Yılbaşı) | M2: New Year's Day (Yılbaşı) | N2: New Year's Day (Yılbaşı) | O2: New Year's Day (Yılbaşı) | P2: New Year's Day (Yılbaşı) | Q2: New Year's Day (Yılbaşı) | R2: Day of the Establishment of the Slovak Republic (Slovakya Cumhuriyeti'nin Kuruluş Günü) | S2: New Year's Day (Yılbaşı) | T2: New Year's Day (Yılbaşı) | U2: New Year's Day (Yılbaşı) | V2: New Year's Day (Yılbaşı) | W2: New Year's Day (Yılbaşı) | X2: New Year's Day (Yılbaşı) | Y2: New Year's Day (Yılbaşı) | Z2: New Year's Day (Yılbaşı) | AA2: New Year's Day (Yılbaşı)
A3: 46024 | W3: New Year's Day Holiday (Yılbaşı Ertesi)
A4: 46028 | C4: Trettondedag jul (Epifani) | R4: Epiphany (Teofani / Üç Kral Bayramı) | X4: Epiphany (Epifani Bayramı) | Z4: Epiphany (Epifani Bayramı)
A5: 46029 | AB5: Coptic Christmas Day (Kıpti Noeli)
A6: 46034 | T6: Zanzibar Revolution Day (Zanzibar Devrim Günü)
A7: 46041 | B7: Martin Luther King Jr. Day
A8: 46042 | W8: Martyrs' Day / National Sorrow Day (Şehitleri Anma Günü)
A9: 46051 | AB9: Revolution Day (25 Ocak Devrimi Anma Günü)
A10: 46069 | M10: Carnival (Karnaval)
A11: 46070 | D11: Spring Festival / Chinese New Year (Bahar Festivali / Çin Yeni Yılı) | M11: Carnival (Karnaval) | Q11: Chinese New Year (Çin Yeni Yılı 1. Gün) | Y11: Korean New Year / Seollal (Kore Yeni Yılı 1. Gün)
A12: 46071 | Q12: Chinese New Year (Çin Yeni Yılı 2. Gün) | Y12: Korean New Year / Seollal (Kore Yeni Yılı 2. Gün)
A13: 46072 | Y13: Korean New Year / Seollal (Kore Yeni Yılı 3. Gün)
A14: 46077 | N14: Independence Day (Bağımsızlık Günü)
A15: 46082 | Y15: Independence Movement Day (Bağımsızlık Hareketi Günü)
A16: 46089 | V16: International Women's Day (Dünya Kadınlar Günü) | W16: International Women's Day (Dünya Kadınlar Günü)
A17: 46098 | G17: St. Patrick's Day (Aziz Patrick Günü) | L17: Revelation of the Qur'an (Kadir Gecesi)
A18: 46100 | AA18: Ramadan Feast Eve (Ramazan Bayramı Arifesi) | AB18: Eid Al-Fitr (Ramazan Bayramı Başlangıcı)
A19: 46101 | L19: Korité / Eid al-Fitr (Ramazan Bayramı) | O19: Eid ul-Fitr (Ramazan Bayramı) | T19: Eid al-Fitr (Ramazan Bayramı) | U19: Independence Day (Bağımsızlık Günü) | V19: Oraza Bayram (Ramazan Bayramı) | W19: Ramazan Bayrami (Ramazan Bayramı 1. Gün) | AA19: Ramadan Feast Day 1 (Ramazan Bayramı 1. Gün)
A20: 46102 | Q20: Hari Raya Puasa (Ramazan Bayramı) | V20: Nowruz / National Spring Holiday (Nevruz / Bahar Bayramı) | W20: Novruz Bayrami / Ramazan Bayrami (Nevruz / Ramazan Bayramı 2. Gün) | AA20: Ramadan Feast Day 2 (Ramazan Bayramı 2. Gün)
A21: 46103 | V21: Nowruz Holiday (Nevruz 2. Gün) | W21: Novruz Bayrami (Nevruz 2. Gün) | AA21: Ramadan Feast Day 3 (Ramazan Bayramı 3. Gün)
A22: 46104 | W22: Novruz Bayrami (Nevruz 3. Gün)
A23: 46105 | W23: Novruz Bayrami (Nevruz 4. Gün)
A24: 46115 | M24: Good Friday (Kutsal Cuma) | N24: Good Friday (Kutsal Cuma) | O24: Good Friday (Kutsal Cuma) | Q24: Good Friday (Kutsal Cuma) | R24: Good Friday (Kutsal Cuma) | S24: Good Friday (Kutsal Cuma) | T24: Good Friday (Kutsal Cuma)
A25: 46117 | N25: Easter Sunday (Paskalya) | X25: Easter Sunday (Paskalya) | Z25: Easter Sunday (Paskalya)
A26: 46118 | L26: Easter Monday (Paskalya Pazartesisi) | O26: Easter Monday (Paskalya Pazartesisi) | P26: Easter Monday (Paskalya Pazartesisi) | R26: Easter Monday (Paskalya Pazartesisi) | S26: Easter Monday (Paskalya Pazartesisi) | T26: Easter Monday (Paskalya Pazartesisi) | X26: Easter Monday (Paskalya Pazartesisi) | Z26: Easter Monday (Paskalya Pazartesisi)
A27: 46119 | T27: Karume Day (Karume Günü)
A28: 46121 | U28: Martyrs' Day (Şehitler Günü)
A29: 46125 | AB29: Sham El-Nessim (Bahar Festivali)
A30: 46135 | AA30: National Sovereignty and Children's Day (Ulusal Egemenlik ve Çocuk Bayramı)
A31: 46137 | X31: Liberation Day (Kurtuluş Günü) | AB31: Sinai Liberation Day (Sinai Kurtuluş Günü)
A32: 46138 | T32: Union Day (Birlik Günü)
A33: 46139 | I33: Koningsdag (Kralın Doğum Günü)
A34: 46143 | D34: Labour Day (İşçi Bayramı) | F34: Tag der Arbeit (İşçi Bayramı) | J34: Fête du Travail (İşçi Bayramı) | L34: Labour Day (İşçi Bayramı) | M34: Labour Day (İşçi Bayramı) | N34: Labor Day / Spring Day (Bahar ve Emek Günü) | O34: Labour Day (İşçi Bayramı) | P34: Labour Day (İşçi Bayramı) | Q34: Labour Day (İşçi Bayramı) | R34: Labour Day (İşçi Bayramı) | T34: Workers' Day (İşçi Bayramı) | U34: Labour Day (İşçi Bayramı) | X34: Labour Day (İşçi Bayramı) | Z34: Labour Day (İşçi Bayramı) | AA34: Labor and Solidarity Day (Emek ve Dayanışma Günü)
A35: 46145 | E35: Święto Konstytucji 3 Maja (Anayasa Günü)
A36: 46147 | Y36: Children's Day (Çocuk Günü)
A37: 46149 | AB37: Labor Day (İşçi Bayramı)
A38: 46150 | R38: Day of Victory over Fascism (Faşizme Karşı Zafer Günü)
A39: 46151 | P39: Europe Day (Avrupa Günü) | W39: Victory Day over Fascism (Faşizme Karşı Zafer Günü)
A40: 46156 | L40: Ascension Day (İsa'nın Göğe Yükselişi) | P40: Ascension Day (İsa'nın Göğe Yükselişi) | S40: Ascension Day (İsa'nın Göğe Yükselişi)
...
